Workbook
Name ACTION: #REF!

Sheet Cover
C2: TEST CASE
B4: Project Name | C4: <Project Name> | F4: Creator
B5: Project Code | C5: <Project Code> | F5: Reviewer/Approver
B6: Document Code | C6: =C5&"_"&"XXX"&"_"&"vx.x" -> <Project Code>_XXX_vx.x | F6: Issue Date
F7: Version
B10: Record of change
B11: Effective Date | C11: Version | D11: Change Item | E11: *A,D,M | F11: Change description | G11: Reference
B12: <Date when these changes are effective> | G12: <List of documents which are referred in this version.>

Sheet Test case List
D1: TEST CASE LIST
B3: Project Name | D3: =Cover!C4 -> <Project Name>
B4: Project Code | D4: =Cover!C5 -> <Project Code>
B5: Test Environment Setup Description | D5: <List enviroment requires in this system 1. Server 2. Database 3. Web Browser ... >
B8: No | C8: Function Name | D8: Sheet Name | E8: Description | F8: Pre-Condition
B9: 1 | C9: FORM FUNCTIONALITY | D9: Module1
B10: 2 | C10: LINK TESTING | D10: Module2
B11: 3 | C11: BUSINESS WORKFLOW | D11: Module3

Sheet Module1
A2: Module Code | B2: Module1 | K2: Pass
A3: Test requirement | B3: <Brief description about requirements which are tested in this sheet> | K3: Fail
A4: Tester
A5: Pass | B5: Fail | D5: Untested | E5: N/A | F5: Number of Test cases | K5: Untesed
A6: =COUNTIF(G9:G997,"Pass") -> 10 | B6: =COUNTIF(G9:G997,"Fail") -> 0 | D6: 0 | E6: =COUNTIF(G$9:G$997,"N/A") -> 0 | F6: 10 | K6: N/A
A8: ID | B8: Test Case Description | C8: Pre-condition | D8: Test Case Procedure | E8: Expected Output | F8: Test data | G8: Result | H8: Test data | I8: Description
A9: TC_FORM_01 | B9: Verify form is displayed correctly | C9: User accesses the correct page containing the form | D9: 1. Access the system | E9: All input fields and buttons are displayed correctly with proper labels | F9: N/A | G9: Pass | H9: N/A | I9: Form UI verification
D10: 2. Navigate to the page containing the form
D11: 3. Observe all input fields
D12: 4. Verify the display of action buttons (Submit, Cancel, Save, etc.)
A13: TC_FORM_02 | B13: Submit form with valid data | C13: Form is ready for use | D13: 1. Open the page containing the form | E13: Form is submitted successfully and no error message is displayed | F13: FormData_01 | G13: Pass | H13: TestDataModule1 | I13: Valid form submission
D14: 2. Enter valid data into all required fields
D15: 3. Review the entered data
D16: 4. Click the Submit button
A17: TC_FORM_03 | B17: Submit form with empty required fields | C17: Form is ready for use | D17: 1. Open the page containing the form | E17: Validation message requesting required input is displayed | F17: FormData_02 | G17: Pass | H17: TestDataModule1 | I17: Required field validation
D18: 2. Leave required fields empty
D19: 3. Click the Submit button
A20: TC_FORM_04 | B20: Submit form with invalid data format | C20: Form is ready for use | D20: 1. Open the page containing the form | E20: Data format validation error message is displayed | F20: FormData_03 | G20: Pass | H20: TestDataModule1 | I20: Data format validation
D21: 2. Enter data in an invalid format (e.g., text in a numeric field)
D22: 3. Click the Submit button
A23: TC_FORM_05 | B23: Verify error message when invalid input is entered | C23: Form is ready for use | D23: 1. Open the page containing the form | E23: Error message is clearly displayed at the correct field | F23: FormData_04 | G23: Pass | H23: TestDataModule1 | I23: Error message display
D24: 2. Enter invalid data
D25: 3. Click the Submit button
D26: 4. Observe the error message
A27: TC_FORM_06 | B27: Verify data is saved after form submission | C27: Form is submitted successfully | D27: 1. Submit the form with valid data | E27: Entered data is saved correctly | F27: FormData_01 | G27: Pass | H27: TestDataModule1 | I27: Data persistence
D28: 2. Navigate to another page
D29: 3. Return to the form page or data list
A30: TC_FORM_07 | B30: Add new data using form | C30: User has permission to add new data | D30: 1. Navigate to the Add New Data page | E30: New data appears successfully in the system | F30: FormData_05 | G30: Pass | H30: TestDataModule1 | I30: Create operation
D31: 2. Enter valid data into all required fields
D32: 3. Click the Submit button
D33: 4. Verify the data list
A34: TC_FORM_08 | B34: Update existing data using form | C34: Existing data is available | D34: 1. Navigate to the data list | E34: Data is updated correctly | F34: FormData_06 | G34: Pass | H34: TestDataModule1 | I34: Update operation
D35: 2. Select a record to edit
D36: 3. Update the information
D37: 4. Click the Submit button
A38: TC_FORM_09 | B38: View data details in form | C38: Existing data is available | D38: 1. Navigate to the data list | E38: Data details are displayed completely and accurately | F38: N/A | G38: Pass | H38: N/A | I38: Read operation
D39: 2. Select the view detail option
A40: TC_FORM_10 | B40: Delete data using form | C40: Existing data is available | D40: 1. Navigate to the data list | E40: Data is removed from the system successfully | F40: FormData_07 | G40: Pass | H40: TestDataModule1 | I40: Delete operation
D41: 2. Select a record to delete
D42: 3. Click the Delete button
...

Sheet Module2
A2: Module Code | B2: Module2 | K2: Pass
A3: Test requirement | B3: <Brief description about requirements which are tested in this sheet> | K3: Fail
A4: Tester
A5: Pass | B5: Fail | D5: Untested | E5: N/A | F5: Number of Test cases | K5: Untesed
A6: =COUNTIF(G10:G998,"Pass") -> 8 | B6: =COUNTIF(G10:G998,"Fail") -> 0 | D6: =F6-E6-B6-A6 -> 0 | E6: =COUNTIF(G$10:G$998,"N/A") -> 0 | F6: =COUNTA(A10:A998) -> 8 | K6: N/A
A8: ID | B8: Test Case Description | C8: Pre-condition | D8: Test Case Procedure | E8: Expected Output | F8: Inter-test case Dependence | G8: Result | H8: Test date | I8: Note
A9: TC_LINK_01 | B9: Verify all internal links navigate to correct pages | C9: User is logged in and system is accessible | D9: 1. Access the system | E9: Each internal link redirects to the correct and expected page without error | F9: N/A | G9: Pass | H9: TestDataModule1 | I9: Internal link navigation
D10: 2. Navigate to the Home page
D11: 3. Identify all internal links (menu links, buttons, text links)
D12: 4. Click each internal link one by one
D13: 5. Observe the destination page after each click
A14: TC_LINK_02 | B14: Verify internal links work from different pages | C14: User is logged in | D14: 1. Navigate to multiple pages (Home, Menu, Cart, Profile) | E14: Internal links work consistently across different pages | F14: N/A | G14: Pass | H14: TestDataModule1 | I14: Internal link consistency
D15: 2. Click internal links available on each page
D16: 3. Observe navigation behavior
A17: TC_LINK_03 | B17: Verify external links (Stripe API) are accessible | C17: System is connected to internet | D17: 1. Access the system | E17: External link to Stripe is accessible and loads correctly | F17: Stripe_URL | G17: Pass | H17: TestDataModule1 | I17: External link integration
D18: 2. Navigate to the payment page
D19: 3. Trigger an action that redirects or connects to Stripe (e.g. Pay Now)
D20: 4. Observe the external link behavior
A21: TC_LINK_04 | B21: Verify external links open correct external resources | C21: System is accessible | D21: 1. Navigate to pages containing external links (e.g. Stripe, policy pages) | E21: External links redirect to correct external systems or resources | F21: External_URLs | G21: Pass | H21: TestDataModule1 | I21: External link validation
D22: 2. Click each external link
D23: 3. Verify destination URL and page content
A24: TC_LINK_05 | B24: Verify system does not contain broken internal links | C24: User is logged in | D24: 1. Navigate through all main pages of the system | E24: No broken links (404, 500 errors) are found | F24: N/A | G24: Pass | H24: TestDataModule1 | I24: Broken link check
D25: 2. Click all visible internal links
D26: 3. Monitor page responses and browser status
A27: TC_LINK_06 | B27: Verify system handles unreachable external links gracefully | C27: External service is unavailable | D27: 1. Simulate external service unavailability (e.g. Stripe down) | E27: System displays appropriate error message or fallback behavior | F27: Stripe_Down | G27: Pass | H27: TestDataModule1 | I27: External link failure handling
D28: 2. Attempt to access the external link
D29: 3. Observe system behavior
A30: TC_LINK_07 | B30: Verify access to non-existing pages is prevented | C30: User is logged in | D30: 1. Manually enter an invalid or non-existing URL | E30: System prevents access and displays error or redirect page | F30: Invalid_URL | G30: Pass | H30: TestDataModule1 | I30: Invalid page access
D31: 2. Press Enter to access the page
A32: TC_LINK_08 | B32: Verify system redirects user when accessing invalid pages | C32: User is logged in | D32: 1. Enter a non-existing page URL | E32: User is redirected to a valid page (e.g. error page or home page) | F32: Invalid_URL | G32: Pass | H32: TestDataModule1 | I32: Page access control
D33: 2. Observe system response
A34: TC_LINK_09 | B34: Verify system redirects user when accessing invalid pages | C34: User is logged in | D34: 1. Enter a non-existing page URL | E34: User is redirected to a valid page (e.g. error page or home page) | F34: Invalid_URL | G34: Pass | H34: TestDataModule1 | I34: Page access control
D35: 2. Observe system response

Sheet Module3
A2: Module Code | B2: Module1 | J2: Pass
A3: Test requirement | B3: <Brief description about requirements which are tested in this sheet> | J3: Fail
A4: Tester
A5: Pass | B5: Fail | C5: Untested | D5: N/A | E5: Number of Test cases | J5: Untesed
A6: =COUNTIF(F9:F998,"Pass") -> 0 | B6: =COUNTIF(F9:F998,"Fail") -> 0 | C6: =E6-D6-B6-A6 -> 10 | D6: =COUNTIF(F$9:F$998,"N/A") -> 0 | E6: =COUNTA(A9:A998) -> 10 | J6: N/A
A8: ID | B8: Test Case Description | C8: Pre-condition | D8: Test Case Procedure | E8: Expected Output | F8: Inter-test case Dependence | G8: Result | H8: Test date | I8: Note
A9: TC_BW_01 | B9: Verify end-to-end order workflow | C9: User has a valid account | D9: 1. Access the system | E9: Order is completed successfully and confirmation page is displayed | F9: BW_Data_01 | G9: Pass | H9: TestDataModule1 | I9: End-to-End workflow
D10: 2. Login with valid credentials
D11: 3. Browse food menu
D12: 4. Add food items to shopping cart
D13: 5. Proceed to checkout
D14: 6. Complete payment
A15: TC_BW_02 | B15: Verify workflow from login to successful payment | C15: User account exists | D15: 1. Login to system | E15: Payment is successful and order status is updated | F15: BW_Data_02 | G15: Pass | H15: TestDataModule1 | I15: Full business flow
D16: 2. Navigate through menu pages
D17: 3. Add items to cart
D18: 4. Checkout and pay using valid payment method
A19: TC_BW_03 | B19: Verify data consistency across pages | C19: User is logged in | D19: 1. Add multiple items to cart | E19: Product list, quantity, and total amount remain consistent | F19: BW_Data_03 | G19: Pass | H19: TestDataModule1 | I19: Data consistency
D20: 2. Navigate between Menu, Cart, and Checkout pages
D21: 3. Observe item list, quantity, and total price
A22: TC_BW_04 | B22: Verify data consistency after page refresh | C22: Items exist in cart | D22: 1. Add items to cart | E22: Cart data is retained correctly after refresh | F22: BW_Data_04 | G22: Pass | H22: TestDataModule1 | I22: State persistence
D23: 2. Refresh the browser page
D24: 3. Navigate to cart again
A25: TC_BW_05 | B25: Verify system behavior when payment is cancelled | C25: User at payment step | D25: 1. Proceed to checkout | E25: System handles cancellation gracefully without data loss | F25: BW_Data_05 | G25: Pass | H25: TestDataModule1 | I25: Interrupted workflow
D26: 2. Initiate payment
D27: 3. Cancel payment process
D28: 4. Return to previous page
A29: TC_BW_06 | B29: Verify workflow when user navigates back during checkout | C29: User is at checkout page | D29: 1. Add items to cart | E29: Cart data remains unchanged and no error occurs | F29: BW_Data_06 | G29: Pass | H29: TestDataModule1 | I29: Navigation handling
D30: 2. Proceed to checkout
D31: 3. Click browser Back button
D32: 4. Return to cart
A33: TC_BW_07 | B33: Verify system prevents duplicate orders on repeated payment | C33: User at payment page | D33: 1. Proceed to checkout | E33: Only one order is created and payment is processed once | F33: BW_Data_07 | G33: Pass | H33: TestDataModule1 | I33: Duplicate prevention
D34: 2. Click Pay button multiple times rapidly
A35: TC_BW_08 | B35: Verify redirection after successful login | C35: User not logged in | D35: 1. Access login page | E35: User is redirected to Home page | F35: BW_Data_08 | G35: Pass | H35: TestDataModule1 | I35: Redirect validation
D36: 2. Login with valid credentials
A37: TC_BW_09 | B37: Verify redirection after successful payment | C37: Payment completed | D37: 1. Complete checkout and payment | E37: User is redirected to order confirmation page | F37: BW_Data_09 | G37: Pass | H37: TestDataModule1 | I37: Post-payment redirect
A38: TC_BW_10 | B38: Verify redirection when accessing protected pages | C38: User logged out | D38: 1. Logout from system | E38: User is redirected to login page | F38: BW_Data_10 | G38: Pass | H38: TestDataModule1 | I38: Access control
D39: 2. Attempt to access protected page via URL

Sheet TestDataModule1
A1: Test Data ID | B1: Username | C1: Password | D1: Role | E1: Email | F1: Account Status | G1: Note
A2: FormData_01 | B2: Dieu Linh | C2: P@ssw0rd123 | D2: Customer | E2: user3@gmail.com | F2: Active | G2: Valid data for successful form submission
A3: FormData_02 | B3: (empty) | C3: P@ssw0rd123 | D3: Customer | E3: user3@gmail.com | F3: Active | G3: Missing required username field
A4: FormData_03 | B4: Dieu Linh | C4: abc123 | D4: Customer | E4: invalid-email-format | F4: Active | G4: Invalid data format (password, email)
A5: FormData_04 | B5: Dieu Linh | C5: short | D5: Customer | E5: user3@gmail.com | F5: Active | G5: Trigger validation error messages
A6: FormData_05 | B6: Dieu Linh | C6: P@ssw0rd456 | D6: Customer | E6: user3@gmail.com | F6: Active | G6: Create new data using form
A7: FormData_06 | B7: Dieu Linh | C7: P@ssw0rd789 | D7: Customer | E7: user3@gmail.com | F7: Active | G7: Update existing data
A8: FormData_07 | B8: Dieu Linh | C8: P@ssw0rd999 | D8: Customer | E8: user3@gmail.com | F8: Active | G8: Delete existing data
A9: N/A | B9: N/A | C9: N/A | D9: N/A | E9: N/A | F9: N/A | G9: Used for UI-only or view-only test cases

Sheet TestDataModule2
A1: Test Data ID | B1: URL / Link Type | C1: Page Name / Source | D1: User State | E1: Network / Service Status | F1: Expected Behavior | G1: Note
A2: LinkData_01 | B2: Internal link | C2: Home → Menu | D2: Logged in | E2: Normal | F2: Navigate to Menu page successfully | G2: Internal navigation
A3: LinkData_02 | B3: Internal link | C3: Menu → Cart | D3: Logged in | E3: Normal | F3: Navigate to Cart page successfully | G3: Internal navigation
A4: LinkData_03 | B4: Internal link | C4: Cart → Profile | D4: Logged in | E4: Normal | F4: Navigate to Profile page successfully | G4: Internal navigation
A5: LinkData_04 | B5: External link (Stripe) | C5: Checkout → Pay Now | D5: Logged in | E5: Internet available | F5: Redirect to Stripe payment page | G5: External integration
A6: LinkData_05 | B6: External link | C6: Footer → Policy page | D6: Logged in | E6: Internet available | F6: Open correct external policy page | G6: External resource
A7: LinkData_06 | B7: Internal link | C7: Multiple pages | D7: Logged in | E7: Normal | F7: No broken links (no 404 / 500 error) | G7: Broken link check
A8: LinkData_07 | B8: External link (Stripe) | C8: Checkout | D8: Logged in | E8: Stripe service down | F8: Show error message or fallback behavior | G8: External failure
A9: LinkData_08 | B9: Invalid URL | C9: Manually entered URL | D9: Logged in | E9: Normal | F9: Access is blocked or error page is shown | G9: Invalid page
A10: LinkData_09 | B10: Invalid URL | C10: Manually entered URL | D10: Logged in | E10: Normal | F10: Redirect to error page or home page | G10: Redirect handing

Sheet TestDataModule3
A1: Test Data ID | B1: User Account | C1: Items in Cart | D1: Quantity | E1: Payment Method | F1: Order Status | G1: User State | H1: Scenario Description | I1: Note
A2: BW_Data_01 | B2: customer01 | C2: bún bò 1, Món lẩu | D2: 1, 1 | E2: Stripe (Valid) | F2: Completed | G2: Logged in | H2: End-to-end order from login to payment | I2: E2E success
A3: BW_Data_02 | B3: customer01 | C3: bún bò 1 | D3: 1 | E3: Stripe (Valid) | F3: Completed | G3: Logged in | H3: Login → browse → add to cart → pay | I3: Full workflow
A4: BW_Data_03 | B4: customer01 | C4: bún bò 1, Pho | D4: 1, 1 | E4: N/A | F4: In progress | G4: Logged in | H4: Navigate between Menu, Cart, Checkout | I4: Data consistency
A5: BW_Data_04 | B5: customer01 | C5: bún bò 1 | D5: 2 | E5: N/A | F5: In cart | G5: Logged in | H5: Refresh page after adding items | I5: State persistence
A6: BW_Data_05 | B6: customer01 | C6: bún bò 1 | D6: 1 | E6: Stripe (Cancelled) | F6: Cancelled | G6: Logged in | H6: Cancel payment during checkout | I6: Payment interruption
A7: BW_Data_06 | B7: customer01 | C7: Món lẩu | D7: 1 | E7: N/A | F7: In checkout | G7: Logged in | H7: Use browser Back button during checkout | I7: Navigation handling
A8: BW_Data_07 | B8: customer01 | C8: bún bò 1 | D8: 1 | E8: Stripe (Valid) | F8: Completed | G8: Logged in | H8: Click Pay button multiple times | I8: Duplicate prevention
A9: BW_Data_08 | B9: customer01 | C9: N/A | D9: N/A | E9: N/A | F9: N/A | G9: Not logged in | H9: Login and redirection to Home page | I9: Login redirect
A10: BW_Data_09 | B10: customer01 | C10: Cơm Code | D10: 1 | E10: Stripe (Valid) | F10: Completed | G10: Logged in | H10: Redirect to confirmation page after payment | I10: Post-payment redirect
A11: BW_Data_10 | B11: customer01 | C11: N/A | D11: N/A | E11: N/A | F11: N/A | G11: Logged out | H11: Access protected page after logout | I11: Access

Sheet Test Report
B1: TEST REPORT
B3: Project Name | C3: <Project Name> | E3: Creator
B4: Project Code | C4: <Project Code> | E4: Reviewer/Approver
B5: Document Code | C5: =C4&"_"&"Test Report"&"_"&"vx.x" -> <Project Code>_Test Report_vx.x | E5: Issue Date | H5: <Date when this test report is created>
B6: Notes | C6: <List modules included in this release> ex: Release 1 includes 2 modules: Module1 and Module2
B10: No | C10: Module code | D10: Pass | E10: Fail | F10: Untested | G10: N/A | H10: Number of test cases
B11: 1 | C11: =Module1!B2 -> Module1 | D11: =Module1!A6 -> 10 | E11: =Module1!B6 -> 0 | F11: =Module1!D6 -> 0 | G11: =Module1!E6 -> 0 | H11: =Module1!F6 -> 10
B12: 2 | C12: =Module2!B2 -> Module2 | D12: 8 | E12: =Module2!B6 -> 0 | F12: =Module2!D6 -> 0 | G12: =Module2!E6 -> 0 | H12: =Module2!F6 -> 8
B13: 3 | C13: Module3 | D13: 10 | E13: 0 | F13: 0 | G13: 0 | H13: 10
C14: Sub total | D14: =SUM(D9:D13) -> 28 | E14: =SUM(E9:E13) -> 0 | F14: =SUM(F9:F13) -> 0 | G14: =SUM(G9:G13) -> 0 | H14: =SUM(H9:H13) -> 28
C16: Test coverage | E16: =(D14+E14)*100/(H14-G14) -> 100 | F16: %
C17: Test successful coverage | E17: =D14*100/(H14-G14) -> 100 | F17: %
